Workbook

Sheet Salespeople
A1: SalespersonID | B1: Salesperson | C1: Segment | D1: PrimarySpecialism | E1: Region | F1: Seniority
A2: SP001 | B2: Alice Brown | C2: Enterprise | D2: Cloud & IT | E2: London | F2: Senior
A3: SP002 | B3: Ben Carter | C3: Enterprise | D3: Cyber Security | E3: London | F3: Senior
A4: SP003 | B4: Chloe Singh | C4: Mid-Market | D4: Modern Workplace | E4: South | F4: Senior
A5: SP004 | B5: Daniel Wilson | C5: Mid-Market | D5: Connectivity | E5: South | F5: Senior
A6: SP005 | B6: Emma Patel | C6: SMB | D6: IT Support | E6: South | F6: Mid
A7: SP006 | B7: Farhan Khan | C7: SMB | D7: Hosted Telephony | E7: London | F7: Mid
A8: SP007 | B8: Grace Taylor | C8: Mid-Market | D8: Cyber Security | E8: Midlands | F8: Mid
A9: SP008 | B9: Harry Evans | C9: Enterprise | D9: Connectivity | E9: Midlands | F9: Mid
A10: SP009 | B10: Isla Ahmed | C10: SMB | D10: Cloud & IT | E10: North | F10: Junior
A11: SP010 | B11: Jack Thomas | C11: SMB | D11: IT Support | E11: North | F11: Junior

Sheet Customers
A1: CustomerID | B1: CustomerName | C1: Segment | D1: Region | E1: CustomerSince | F1: ExistingCustomer
A2: CUST0001 | B2: Customer 0001 | C2: SMB | D2: South | E2: 45986 | F2: 0
A3: CUST0002 | B3: Customer 0002 | C3: Enterprise | D3: Midlands | E3: 45435 | F3: 0
A4: CUST0003 | B4: Customer 0003 | C4: Mid-Market | D4: North | E4: 45664 | F4: 1
A5: CUST0004 | B5: Customer 0004 | C5: Mid-Market | D5: London | E5: 44904 | F5: 0
A6: CUST0005 | B6: Customer 0005 | C6: SMB | D6: Midlands | E6: 45100 | F6: 1
A7: CUST0006 | B7: Customer 0006 | C7: SMB | D7: South | E7: 43728 | F7: 0
A8: CUST0007 | B8: Customer 0007 | C8: SMB | D8: London | E8: 45253 | F8: 1
A9: CUST0008 | B9: Customer 0008 | C9: Enterprise | D9: London | E9: 45657 | F9: 1
A10: CUST0009 | B10: Customer 0009 | C10: Mid-Market | D10: London | E10: 45859 | F10: 1
A11: CUST0010 | B11: Customer 0010 | C11: Mid-Market | D11: Midlands | E11: 44089 | F11: 1
A12: CUST0011 | B12: Customer 0011 | C12: SMB | D12: South | E12: 44482 | F12: 0
A13: CUST0012 | B13: Customer 0012 | C13: Enterprise | D13: London | E13: 44346 | F13: 1
... A121: CUST0120 | B121: Customer 0120 | C121: Mid-Market | D121: Midlands | E121: 44150 | F121: 1

Sheet CustomerProducts
A1: CustomerID | B1: Product | C1: MonthlyRevenue | D1: Active
A2: CUST0001 | B2: Connectivity | C2: 8152.21 | D2: 1
A3: CUST0002 | B3: Modern Workplace | C3: 765.32 | D3: 1
A4: CUST0002 | B4: IT Support | C4: 8639.31 | D4: 1
A5: CUST0003 | B5: IT Support | C5: 4497.93 | D5: 1
A6: CUST0003 | B6: Hosted Telephony | C6: 4589.32 | D6: 1
A7: CUST0003 | B7: Cyber Security | C7: 1024.57 | D7: 1
A8: CUST0004 | B8: Modern Workplace | C8: 6845.66 | D8: 1
A9: CUST0005 | B9: Cyber Security | C9: 8964.6 | D9: 1
A10: CUST0005 | B10: Telco Support | C10: 786.08 | D10: 1
A11: CUST0005 | B11: Connectivity | C11: 6712.21 | D11: 1
A12: CUST0006 | B12: Connectivity | C12: 7581.59 | D12: 1
A13: CUST0007 | B13: Cyber Security | C13: 7450.18 | D13: 1
... A238: CUST0120 | B238: IT Support | C238: 1220.76 | D238: 1

Sheet Activities
A1: SalespersonID | B1: ActivityDate | C1: ActivityType | D1: ActivityPurpose | E1: DurationMinutes
A2: SP001 | B2: 45845 | C2: Email | D2: New Business | E2: 17
A3: SP001 | B3: 45664 | C3: Email | D3: New Business | E3: 14
A4: SP001 | B4: 45790 | C4: Reachout | D4: Upsell | E4: 5
A5: SP001 | B5: 45892 | C5: Call | D5: Cross-sell | E5: 15
A6: SP001 | B6: 45702 | C6: Proposal | D6: Upsell | E6: 7
A7: SP001 | B7: 45971 | C7: Proposal | D7: New Business | E7: 10
A8: SP001 | B8: 45906 | C8: Reachout | D8: New Business | E8: 12
A9: SP001 | B9: 45688 | C9: Meeting | D9: Cross-sell | E9: 63
A10: SP001 | B10: 45680 | C10: Call | D10: New Business | E10: 16
A11: SP001 | B11: 45817 | C11: Call | D11: Cross-sell | E11: 8
A12: SP001 | B12: 46020 | C12: Call | D12: Upsell | E12: 29
A13: SP001 | B13: 45815 | C13: Call | D13: New Business | E13: 18
... A4192: SP010 | B4192: 46005 | C4192: Reachout | D4192: Retention | E4192: 7

Sheet Opportunities
A1: OpportunityID | B1: CustomerID | C1: SalespersonID | D1: CreatedDate | E1: CloseDate | F1: Product | G1: OpportunityType | H1: Stage | I1: PipelineValue | J1: ExpectedGrossProfit | K1: SalesCycleDays | L1: DataOrigin | M1: ExpectedCloseDate | N1: PipelineStage | O1: WinProbability | P1: ForecastCategory | Q1: LastActivityDate | R1: NextStep | S1: NextStepDueDate | T1: DaysInStage | U1: PipelineRisk
A2: OPP0094 | B2: CUST0034 | C2: SP004 | D2: 45659 | E2: 45692 | F2: Connectivity | G2: Cross-sell | H2: Won | I2: 1788.66 | J2: 726.06 | K2: 33 | L2: Original Workbook | M2: 45692 | N2: Historical | O2: 1 | P2: Historical | R2: Historical record | T2: 0 | U2: Historical
A3: OPP0003 | B3: CUST0119 | C3: SP002 | D3: 45660 | E3: 45777 | F3: Telco Support | G3: Cross-sell | H3: Open | I3: 3696.02 | J3: 1951 | K3: 117 | L3: Original Workbook | M3: 45777 | N3: Historical | O3: 0 | P3: Historical | R3: Historical record | T3: 0 | U3: Historical
A4: OPP0126 | B4: CUST0080 | C4: SP009 | D4: 45660 | E4: 45786 | F4: Connectivity | G4: Cross-sell | H4: Lost | I4: 2830.69 | J4: 939.53 | K4: 126 | L4: Original Workbook | M4: 45786 | N4: Historical | O4: 0 | P4: Historical | R4: Historical record | T4: 0 | U4: Historical
A5: OPP0110 | B5: CUST0076 | C5: SP005 | D5: 45661 | E5: 45678 | F5: Telco Support | G5: Cross-sell | H5: Open | I5: 3584.49 | J5: 1759.62 | K5: 17 | L5: Original Workbook | M5: 45678 | N5: Historical | O5: 0 | P5: Historical | R5: Historical record | T5: 0 | U5: Historical
A6: OPP0164 | B6: CUST0007 | C6: SP008 | D6: 45661 | E6: 45777 | F6: Cloud IT | G6: Renewal | H6: Won | I6: 6468.07 | J6: 2325.43 | K6: 116 | L6: Original Workbook | M6: 45777 | N6: Historical | O6: 1 | P6: Historical | R6: Historical record | T6: 0 | U6: Historical
A7: OPP0313 | B7: CUST0056 | C7: SP009 | D7: 45661 | E7: 45749 | F7: Cloud IT | G7: Cross-sell | H7: Open | I7: 8200.11 | J7: 4264.98 | K7: 88 | L7: Original Workbook | M7: 45749 | N7: Historical | O7: 0 | P7: Historical | R7: Historical record | T7: 0 | U7: Historical
A8: OPP0052 | B8: CUST0077 | C8: SP010 | D8: 45663 | E8: 45752 | F8: Hosted Telephony | G8: Renewal | H8: Won | I8: 3726.06 | J8: 1361.09 | K8: 89 | L8: Original Workbook | M8: 45752 | N8: Historical | O8: 1 | P8: Historical | R8: Historical record | T8: 0 | U8: Historical
A9: OPP0028 | B9: CUST0057 | C9: SP004 | D9: 45664 | E9: 45791 | F9: IT Support | G9: Cross-sell | H9: Won | I9: 696.87 | J9: 240.87 | K9: 127 | L9: Original Workbook | M9: 45791 | N9: Historical | O9: 1 | P9: Historical | R9: Historical record | T9: 0 | U9: Historical
A10: OPP0270 | B10: CUST0090 | C10: SP002 | D10: 45670 | E10: 45795 | F10: Hosted Telephony | G10: Renewal | H10: Lost | I10: 2610.66 | J10: 912.95 | K10: 125 | L10: Original Workbook | M10: 45795 | N10: Historical | O10: 0 | P10: Historical | R10: Historical record | T10: 0 | U10: Historical
A11: OPP0033 | B11: CUST0065 | C11: SP006 | D11: 45672 | E11: 45689 | F11: Cloud IT | G11: Cross-sell | H11: Lost | I11: 2041.86 | J11: 866.84 | K11: 17 | L11: Original Workbook | M11: 45689 | N11: Historical | O11: 0 | P11: Historical | R11: Historical record | T11: 0 | U11: Historical
A12: OPP0113 | B12: CUST0057 | C12: SP004 | D12: 45672 | E12: 45800 | F12: Modern Workplace | G12: New Customer | H12: Open | I12: 7083.03 | J12: 3848.21 | K12: 128 | L12: Original Workbook | M12: 45800 | N12: Historical | O12: 0 | P12: Historical | R12: Historical record | T12: 0 | U12: Historical
A13: OPP0196 | B13: CUST0007 | C13: SP010 | D13: 45672 | E13: 45732 | F13: Cloud IT | G13: New Customer | H13: Lost | I13: 10581.02 | J13: 4655.49 | K13: 60 | L13: Original Workbook | M13: 45732 | N13: Historical | O13: 0 | P13: Historical | R13: Historical record | T13: 0 | U13: Historical
... A321: OPP0292 | B321: CUST0098 | C321: SP002 | D321: 45991 | E321: 46096 | F321: Hosted Telephony | G321: Renewal | H321: Won | I321: 13005.18 | J321: 5937.21 | K321: 105 | L321: Original Workbook | M321: 46096 | N321: Historical | O321: 1 | P321: Historical | R321: Historical record | T321: 0 | U321: Historical
A322: OPP0347 | B322: CUST0010 | C322: SP007 | D322: 46027 | E322: 46129 | F322: Hosted Telephony | G322: Upsell | H322: Lost | I322: 50726.41 | J322: 21183.17 | K322: 102 | L322: Synthetic Current Year | M322: 46129 | N322: Lost | O322: 0 | P322: Closed | Q322: 46157 | R322: Closed opportunity review | T322: 0 | U322: Low
A323: OPP0380 | B323: CUST0008 | C323: SP010 | D323: 46028 | F323: Telco Support | G323: New Customer | H323: Open | I323: 80209.03 | J323: 27174.92 | K323: 221 | L323: Synthetic Current Year | M323: 46340 | N323: Discovery | O323: 0.115 | P323: Pipeline | Q323: 46074 | R323: Confirm business outcomes and executive sponsor | S323: 46265 | T323: 24 | U323: High
A324: OPP0464 | B324: CUST0075 | C324: SP004 | D324: 46028 | E324: 46130 | F324: Cyber Security | G324: Upsell | H324: Won | I324: 85064.4 | J324: 22989.02 | K324: 102 | L324: Synthetic Current Year | M324: 46130 | N324: Won | O324: 1 | P324: Closed | Q324: 46067 | R324: Closed opportunity review | T324: 0 | U324: Low
A325: OPP0374 | B325: CUST0068 | C325: SP004 | D325: 46029 | F325: Hosted Telephony | G325: Cross-sell | H325: Open | I325: 54757.36 | J325: 19773.51 | K325: 220 | L325: Synthetic Current Year | M325: 46274 | N325: Negotiation | O325: 0.745 | P325: Best Case | Q325: 46082 | R325: Resolve commercial and procurement actions | S325: 46260 | T325: 69 | U325: High
A326: OPP0405 | B326: CUST0012 | C326: SP005 | D326: 46029 | E326: 46053 | F326: Telco Support | G326: New Customer | H326: Won | I326: 29349.88 | J326: 9547.68 | K326: 24 | L326: Synthetic Current Year | M326: 46053 | N326: Won | O326: 1 | P326: Closed | Q326: 46210 | R326: Closed opportunity review | T326: 0 | U326: Low
A327: OPP0454 | B327: CUST0036 | C327: SP004 | D327: 46029 | F327: Cyber Security | G327: Cross-sell | H327: Open | I327: 34131.35 | J327: 11679.43 | K327: 220 | L327: Synthetic Current Year | M327: 46318 | N327: Negotiation | O327: 0.753 | P327: Best Case | Q327: 46226 | R327: Resolve commercial and procurement actions | S327: 46252 | T327: 56 | U327: High
A328: OPP0438 | B328: CUST0079 | C328: SP008 | D328: 46034 | E328: 46149 | F328: Cyber Security | G328: New Customer | H328: Won | I328: 32682.42 | J328: 9910.78 | K328: 115 | L328: Synthetic Current Year | M328: 46149 | N328: Won | O328: 1 | P328: Closed | Q328: 46227 | R328: Closed opportunity review | T328: 0 | U328: Low
A329: OPP0325 | B329: CUST0061 | C329: SP005 | D329: 46035 | F329: IT Support | G329: New Customer | H329: Open | I329: 24312.36 | J329: 10661.43 | K329: 214 | L329: Synthetic Current Year | M329: 46356 | N329: Qualification | O329: 0.296 | P329: Pipeline | Q329: 46167 | R329: Validate budget, authority, need, and timeline | S329: 46265 | T329: 48 | U329: High
A330: OPP0337 | B330: CUST0119 | C330: SP007 | D330: 46035 | F330: Cyber Security | G330: New Customer | H330: Open | I330: 18967.95 | J330: 8029.31 | K330: 214 | L330: Synthetic Current Year | M330: 46388 | N330: Negotiation | O330: 0.776 | P330: Best Case | Q330: 46236 | R330: Resolve commercial and procurement actions | S330: 46253 | T330: 55 | U330: Medium
A331: OPP0420 | B331: CUST0039 | C331: SP010 | D331: 46035 | E331: 46130 | F331: Connectivity | G331: Cross-sell | H331: Won | I331: 50601.39 | J331: 20081.17 | K331: 95 | L331: Synthetic Current Year | M331: 46130 | N331: Won | O331: 1 | P331: Closed | Q331: 46135 | R331: Closed opportunity review | T331: 0 | U331: Low
A332: OPP0421 | B332: CUST0043 | C332: SP001 | D332: 46035 | E332: 46089 | F332: Telco Support | G332: Cross-sell | H332: Won | I332: 44405.4 | J332: 18634.27 | K332: 54 | L332: Synthetic Current Year | M332: 46089 | N332: Won | O332: 1 | P332: Closed | Q332: 46061 | R332: Closed opportunity review | T332: 0 | U332: Low
A333: OPP0476 | B333: CUST0042 | C333: SP006 | D333: 46035 | F333: Hosted Telephony | G333: Cross-sell | H333: Open | I333: 25965.51 | J333: 8749 | K333: 214 | L333: Synthetic Current Year | M333: 46310 | N333: Solution Design | O333: 0.485 | P333: Pipeline | Q333: 46065 | R333: Complete technical scope and solution workshop | S333: 46262 | T333: 51 | U333: High
A334: OPP0412 | B334: CUST0022 | C334: SP002 | D334: 46036 | E334: 46093 | F334: Connectivity | G334: Cross-sell | H334: Won | I334: 25175.44 | J334: 7841.58 | K334: 57 | L334: Synthetic Current Year | M334: 46093 | N334: Won | O334: 1 | P334: Closed | Q334: 46162 | R334: Closed opportunity review | T334: 0 | U334: Low
A335: OPP0470 | B335: CUST0054 | C335: SP010 | D335: 46037 | E335: 46127 | F335: Cloud IT | G335: Cross-sell | H335: Won | I335: 40999.2 | J335: 18292.96 | K335: 90 | L335: Synthetic Current Year | M335: 46127 | N335: Won | O335: 1 | P335: Closed | Q335: 46093 | R335: Closed opportunity review | T335: 0 | U335: Low
A336: OPP0354 | B336: CUST0037 | C336: SP004 | D336: 46038 | F336: Modern Workplace | G336: Upsell | H336: Open | I336: 38192.01 | J336: 10378.23 | K336: 211 | L336: Synthetic Current Year | M336: 46267 | N336: Proposal | O336: 0.625 | P336: Best Case | Q336: 46180 | R336: Review proposal and commercial assumptions | S336: 46261 | T336: 20 | U336: High
A337: OPP0366 | B337: CUST0115 | C337: SP006 | D337: 46041 | F337: Cyber Security | G337: Cross-sell | H337: Open | I337: 21413.75 | J337: 9362.47 | K337: 208 | L337: Synthetic Current Year | M337: 46309 | N337: Proposal | O337: 0.656 | P337: Best Case | Q337: 46089 | R337: Review proposal and commercial assumptions | S337: 46264 | T337: 33 | U337: High
A338: OPP0389 | B338: CUST0077 | C338: SP009 | D338: 46041 | E338: 46149 | F338: Cyber Security | G338: Upsell | H338: Lost | I338: 22658.52 | J338: 8192.75 | K338: 108 | L338: Synthetic Current Year | M338: 46149 | N338: Lost | O338: 0 | P338: Closed | Q338: 46151 | R338: Closed opportunity review | T338: 0 | U338: Low
A339: OPP0407 | B339: CUST0100 | C339: SP007 | D339: 46042 | F339: Cyber Security | G339: Cross-sell | H339: Open | I339: 56100.81 | J339: 19798.25 | K339: 207 | L339: Synthetic Current Year | M339: 46334 | N339: Verbal Commit | O339: 0.855 | P339: Commit | Q339: 46177 | R339: Confirm signature and implementation handover date | S339: 46252 | T339: 7 | U339: High
A340: OPP0426 | B340: CUST0120 | C340: SP006 | D340: 46043 | F340: Connectivity | G340: Cross-sell | H340: Open | I340: 83943.13 | J340: 38907.29 | K340: 206 | L340: Synthetic Current Year | M340: 46379 | N340: Qualification | O340: 0.309 | P340: Pipeline | Q340: 46193 | R340: Validate budget, authority, need, and timeline | S340: 46253 | T340: 37 | U340: High
A341: OPP0353 | B341: CUST0114 | C341: SP003 | D341: 46044 | F341: Hosted Telephony | G341: New Customer | H341: Open | I341: 17862.74 | J341: 5431.15 | K341: 205 | L341: Synthetic Current Year | M341: 46354 | N341: Verbal Commit | O341: 0.857 | P341: Commit | Q341: 46215 | R341: Confirm signature and implementation handover date | S341: 46253 | T341: 65 | U341: High
A342: OPP0378 | B342: CUST0071 | C342: SP008 | D342: 46048 | E342: 46140 | F342: Modern Workplace | G342: New Customer | H342: Won | I342: 26073.3 | J342: 11372.91 | K342: 92 | L342: Synthetic Current Year | M342: 46140 | N342: Won | O342: 1 | P342: Closed | Q342: 46075 | R342: Closed opportunity review | T342: 0 | U342: Low
A343: OPP0452 | B343: CUST0013 | C343: SP002 | D343: 46048 | F343: Cloud IT | G343: New Customer | H343: Open | I343: 21391.59 | J343: 9944.3 | K343: 201 | L343: Synthetic Current Year | M343: 46298 | N343: Negotiation | O343: 0.803 | P343: Best Case | Q343: 46053 | R343: Resolve commercial and procurement actions | S343: 46257 | T343: 80 | U343: High
A344: OPP0460 | B344: CUST0023 | C344: SP010 | D344: 46048 | E344: 46131 | F344: Hosted Telephony | G344: Upsell | H344: Lost | I344: 35234.04 | J344: 15035.53 | K344: 83 | L344: Synthetic Current Year | M344: 46131 | N344: Lost | O344: 0 | P344: Closed | Q344: 46198 | R344: Closed opportunity review | T344: 0 | U344: Low
A345: OPP0463 | B345: CUST0090 | C345: SP003 | D345: 46048 | F345: IT Support | G345: New Customer | H345: Open | I345: 12000 | J345: 3639.75 | K345: 201 | L345: Synthetic Current Year | M345: 46335 | N345: Verbal Commit | O345: 0.851 | P345: Commit | Q345: 46174 | R345: Confirm signature and implementation handover date | S345: 46255 | T345: 79 | U345: High
A346: OPP0408 | B346: CUST0002 | C346: SP008 | D346: 46049 | F346: Connectivity | G346: Upsell | H346: Open | I346: 38040.49 | J346: 15740.63 | K346: 200 | L346: Synthetic Current Year | M346: 46389 | N346: Solution Design | O346: 0.451 | P346: Pipeline | Q346: 46147 | R346: Complete technical scope and solution workshop | S346: 46257 | T346: 36 | U346: High
A347: OPP0376 | B347: CUST0061 | C347: SP006 | D347: 46050 | E347: 46107 | F347: IT Support | G347: New Customer | H347: Lost | I347: 13593.44 | J347: 4353.55 | K347: 57 | L347: Synthetic Current Year | M347: 46107 | N347: Lost | O347: 0 | P347: Closed | Q347: 46182 | R347: Closed opportunity review | T347: 0 | U347: Low
...

Sheet SynergyReferrals
A1: ReferralID | B1: ReferralDate | C1: FromSalespersonID | D1: ToSalespersonID | E1: ProductArea | F1: ReferralType | G1: ReferralStatus
A2: REF0001 | B2: 45699 | C2: SP008 | D2: SP004 | E2: Cyber Security | F2: Expansion Opportunity | G2: Accepted
A3: REF0002 | B3: 45798 | C3: SP001 | D3: SP002 | E3: Modern Workplace | F3: Existing Customer | G3: Converted
A4: REF0003 | B4: 45731 | C4: SP001 | D4: SP003 | E4: Cloud IT | F4: Existing Customer | G4: Accepted
A5: REF0004 | B5: 45949 | C5: SP007 | D5: SP001 | E5: Cloud IT | F5: Expansion Opportunity | G5: Accepted
A6: REF0005 | B6: 45916 | C6: SP008 | D6: SP004 | E6: IT Support | F6: Warm Lead | G6: Converted
A7: REF0006 | B7: 45982 | C7: SP006 | D7: SP008 | E7: IT Support | F7: Expansion Opportunity | G7: Accepted
A8: REF0007 | B8: 45889 | C8: SP003 | D8: SP005 | E8: IT Support | F8: Expansion Opportunity | G8: Converted
A9: REF0008 | B9: 45795 | C9: SP009 | D9: SP001 | E9: Cyber Security | F9: Warm Lead | G9: Converted
A10: REF0009 | B10: 45732 | C10: SP004 | D10: SP006 | E10: Cloud IT | F10: Warm Lead | G10: Accepted
A11: REF0010 | B11: 45912 | C11: SP009 | D11: SP001 | E11: Cloud IT | F11: Expansion Opportunity | G11: Converted
A12: REF0011 | B12: 45989 | C12: SP001 | D12: SP003 | E12: IT Support | F12: Warm Lead | G12: Accepted
A13: REF0012 | B13: 45953 | C13: SP001 | D13: SP003 | E13: Modern Workplace | F13: Existing Customer | G13: Converted
... A121: REF0120 | B121: 45711 | C121: SP006 | D121: SP008 | E121: Telco Support | F121: Warm Lead | G121: Converted

Sheet SynergyMap
A1: FromSalespersonID | B1: ToSalespersonID | C1: SynergyType | D1: SynergyStrength
A2: SP001 | B2: SP002 | C2: Cloud & IT + Cyber Security | D2: 0.85
A3: SP001 | B3: SP003 | C3: Cloud & IT + Modern Workplace | D3: 0.75
A4: SP001 | B4: SP004 | C4: Cloud & IT + Connectivity | D4: 0.65
A5: SP002 | B5: SP003 | C5: Cyber Security + Modern Workplace | D5: 0.8
A6: SP002 | B6: SP007 | C6: Cyber Security + Cyber Security | D6: 0.7
A7: SP003 | B7: SP005 | C7: Modern Workplace + IT Support | D7: 0.75
A8: SP004 | B8: SP006 | C8: Connectivity + Hosted Telephony | D8: 0.9
A9: SP004 | B9: SP008 | C9: Connectivity + Connectivity | D9: 0.7
A10: SP005 | B10: SP006 | C10: IT Support + Hosted Telephony | D10: 0.65
A11: SP005 | B11: SP010 | C11: IT Support + IT Support | D11: 0.55
A12: SP006 | B12: SP008 | C12: Hosted Telephony + Connectivity | D12: 0.8
A13: SP007 | B13: SP001 | C13: Cyber Security + Cloud & IT | D13: 0.75
... A16: SP010 | B16: SP005 | C16: IT Support + IT Support | D16: 0.6

Sheet MonthlyPerformance
A1: Month | B1: SalespersonID | C1: CustomerReachouts | D1: Meetings | E1: OpportunitiesCreated | F1: OpportunitiesWon | G1: NewCustomers | H1: CrossSellOpportunities | I1: Revenue | J1: GrossProfit | K1: CrossSellRevenue | L1: TargetAttainment | M1: RetentionRate | N1: WinRate | O1: GrossMarginPct | P1: ReachoutsPerMeeting | Q1: MeetingsPerOpportunity | R1: ReachoutsPerOpportunity | S1: MeetingsPerWin | T1: RevenuePerMeeting | U1: GrossProfitPerMeeting | V1: RevenuePerOpportunity | W1: GrossProfitPerOpportunity | X1: WinsPer100Reachouts | Y1: CrossSellRevenuePct | Z1: CrossSellOpportunityRate | AA1: NewCustomersPerWin | AB1: GrossProfitPerReachout | AC1: DataOrigin
A2: 45658 | B2: SP001 | C2: 64 | D2: 18 | E2: 7 | F2: 2 | G2: 1 | H2: 3 | I2: 33703.35 | J2: 10586.22 | K2: 2620.29 | L2: 0.98 | M2: 0.82 | N2: 0.28571429 | AC2: Original Workbook
A3: 45658 | B3: SP002 | C3: 45 | D3: 25 | E3: 5 | F3: 2 | G3: 3 | H3: 1 | I3: 59156.62 | J3: 20482.38 | K3: 6041.66 | L3: 0.97 | M3: 0.74 | N3: 0.4 | AC3: Original Workbook
A4: 45658 | B4: SP003 | C4: 56 | D4: 12 | E4: 7 | F4: 3 | G4: 0 | H4: 0 | I4: 45363.19 | J4: 16396.76 | K4: 5143.43 | L4: 0.88 | M4: 0.93 | N4: 0.42857143 | AC4: Original Workbook
A5: 45658 | B5: SP004 | C5: 37 | D5: 22 | E5: 4 | F5: 2 | G5: 0 | H5: 4 | I5: 39873.12 | J5: 12545.78 | K5: 2227.07 | L5: 0.76 | M5: 0.74 | N5: 0.5 | AC5: Original Workbook
A6: 45658 | B6: SP005 | C6: 46 | D6: 11 | E6: 5 | F6: 2 | G6: 1 | H6: 3 | I6: 45876.88 | J6: 16744.16 | K6: 3982.78 | L6: 0.78 | M6: 0.62 | N6: 0.4 | AC6: Original Workbook
A7: 45658 | B7: SP006 | C7: 37 | D7: 11 | E7: 5 | F7: 2 | G7: 1 | H7: 1 | I7: 19918.1 | J7: 8335.88 | K7: 1043.22 | L7: 0.89 | M7: 0.97 | N7: 0.4 | AC7: Original Workbook
A8: 45658 | B8: SP007 | C8: 41 | D8: 11 | E8: 3 | F8: 0 | G8: 0 | H8: 2 | I8: 5876.93 | J8: 1663.44 | K8: 200.62 | L8: 1.12 | M8: 0.61 | N8: 0 | AC8: Original Workbook
A9: 45658 | B9: SP008 | C9: 36 | D9: 13 | E9: 3 | F9: 2 | G9: 1 | H9: 1 | I9: 28291.07 | J9: 7943.87 | K9: 2935.95 | L9: 0.9 | M9: 0.84 | N9: 0.66666667 | AC9: Original Workbook
A10: 45658 | B10: SP009 | C10: 47 | D10: 9 | E10: 5 | F10: 4 | G10: 0 | H10: 0 | I10: 35008.7 | J10: 10302.32 | K10: 3630.64 | L10: 0.89 | M10: 0.69 | N10: 0.8 | AC10: Original Workbook
A11: 45658 | B11: SP010 | C11: 25 | D11: 19 | E11: 5 | F11: 3 | G11: 0 | H11: 1 | I11: 27876.07 | J11: 9242.94 | K11: 987.89 | L11: 0.93 | M11: 1.05 | N11: 0.6 | AC11: Original Workbook
A12: 45689 | B12: SP001 | C12: 54 | D12: 14 | E12: 6 | F12: 3 | G12: 0 | H12: 3 | I12: 48034.46 | J12: 17072.97 | K12: 2146.66 | L12: 1.1 | M12: 0.75 | N12: 0.5 | AC12: Original Workbook
A13: 45689 | B13: SP002 | C13: 48 | D13: 18 | E13: 6 | F13: 3 | G13: 2 | H13: 1 | I13: 62337.2 | J13: 19516.81 | K13: 7424.06 | L13: 1.03 | M13: 1.01 | N13: 0.5 | AC13: Original Workbook
... A201: 46235 | B201: SP010 | C201: 15 | D201: 4 | E201: 2 | F201: 0 | G201: 0 | H201: 0 | I201: 0 | J201: 0 | K201: 0 | L201: 0 | M201: 0.47 | N201: 0 | AC201: Synthetic Current Year

Sheet Targets
A1: SalespersonID | B1: AnnualRevenueTarget | C1: AnnualNewCustomerTarget | D1: AnnualCrossSellTarget
A2: SP001 | B2: 550000 | C2: 20 | D2: 25
A3: SP002 | B3: 650000 | C3: 15 | D3: 20
A4: SP003 | B4: 450000 | C4: 15 | D4: 25
A5: SP004 | B5: 650000 | C5: 15 | D5: 25
A6: SP005 | B6: 650000 | C6: 10 | D6: 20
A7: SP006 | B7: 750000 | C7: 15 | D7: 15
A8: SP007 | B8: 650000 | C8: 20 | D8: 25
A9: SP008 | B9: 550000 | C9: 15 | D9: 30
A10: SP009 | B10: 550000 | C10: 15 | D10: 20
A11: SP010 | B11: 450000 | C11: 10 | D11: 25

Sheet FeatureDictionary
A1: Feature | B1: Category | C1: Definition | D1: WhyItMatters
A2: CustomerReachouts | B2: Activity | C2: Number of customer/prospect reachouts | D2: Activity level
A3: Meetings | B3: Activity | C3: Customer/prospect meetings | D3: Engagement quality/volume
A4: OpportunitiesCreated | B4: Pipeline | C4: New opportunities created | D4: Pipeline generation
A5: OpportunitiesWon | B5: Outcome | C5: Closed-won opportunities | D5: Conversion
A6: WinRate | B6: Outcome | C6: Won opportunities / opportunities | D6: Sales effectiveness
A7: Revenue | B7: Outcome | C7: Revenue generated | D7: Primary commercial outcome
A8: GrossProfit | B8: Outcome | C8: Gross profit generated | D8: Profitability
A9: NewCustomers | B9: Growth | C9: New customers acquired | D9: New logo acquisition
A10: CrossSellOpportunities | B10: Growth | C10: Cross-sell opportunities created | D10: Account expansion
A11: CrossSellRevenue | B11: Growth | C11: Revenue from cross-sell | D11: Account expansion
A12: RetentionRate | B12: Customer | C12: Customer retention measure | D12: Account health
... A56: AchievabilityScore | B56: Pipeline | C56: Coverage, weighted coverage, and YTD pace combined into a transparent 0-100 score | D56: Supports manager judgement about annual target risk

Sheet ExampleModelOutput
A1: SalespersonID | B1: Salesperson | C1: PerformanceScore | D1: PredictedRevenue | E1: BenchmarkRevenue | F1: PerformanceGap | G1: PrimaryGap | H1: RecommendedAction
A2: SP001 | B2: Alice Brown | C2: 91 | D2: 675000 | E2: 640000 | F2: 35000 | G2: Cross-sell + Cyber Security | H2: Increase cross-sell discovery across existing Cloud customers
A3: SP005 | B3: Emma Patel | C3: 73 | D3: 465000 | E3: 540000 | F3: -75000 | G3: Meetings + Opportunity Creation | H3: Increase qualified meetings and multi-service discovery
A4: SP009 | B4: Isla Ahmed | C4: 61 | D4: 320000 | E4: 455000 | F4: -135000 | G4: New Customers + Meetings | H4: Increase prospecting and partner/referral activity

Sheet ExistingCustomerBilling
A1: BillingID | B1: CustomerID | C1: BillingMonth | D1: ServiceCategory | E1: Service | F1: ContractID | G1: AccountOwnerID | H1: BillingType | I1: MRR | J1: OneOffCharges | K1: UsageCharges | L1: DiscountAmount | M1: TotalBilled | N1: GrossMarginPct | O1: GrossProfit | P1: BillingStatus | Q1: PaymentStatus | R1: IsRecurring | S1: ContractTermMonths | T1: RenewalDate | U1: BillingContractServiceKey | V1: ContractLinkStatus | W1: ContractLinkNote
A2: BILL00001 | B2: CUST0001 | C2: 45658 | D2: Support | E2: Telco Support | F2: CTR-0001-01 | G2: SP001 | H2: Recurring + Usage | I2: 406 | J2: 0 | K2: 24.63 | L2: 0 | M2: 430.63 | N2: 0.26 | O2: 111.96 | P2: Billed | Q2: Paid | R2: 1 | S2: 24 | T2: 46143 | U2: CUST0001|Telco Support | V2: Linked | W2: Billing row links to matching customer/service contract
A3: BILL00002 | B3: CUST0001 | C3: 45689 | D3: Support | E3: Telco Support | F3: CTR-0001-01 | G3: SP001 | H3: Recurring + Usage | I3: 406 | J3: 0 | K3: 21.68 | L3: 20.3 | M3: 407.38 | N3: 0.33 | O3: 134.44 | P3: Billed | Q3: Pending | R3: 1 | S3: 24 | T3: 46143 | U3: CUST0001|Telco Support | V3: Linked | W3: Billing row links to matching customer/service contract
A4: BILL00003 | B4: CUST0001 | C4: 45717 | D4: Support | E4: Telco Support | F4: CTR-0001-01 | G4: SP001 | H4: Recurring + Usage | I4: 406 | J4: 0 | K4: 24.53 | L4: 0 | M4: 430.53 | N4: 0.35 | O4: 150.69 | P4: Billed | Q4: Paid | R4: 1 | S4: 24 | T4: 46143 | U4: CUST0001|Telco Support | V4: Linked | W4: Billing row links to matching customer/service contract
A5: BILL00004 | B5: CUST0001 | C5: 45748 | D5: Support | E5: Telco Support | F5: CTR-0001-01 | G5: SP001 | H5: Recurring + Usage | I5: 406 | J5: 0 | K5: 9.24 | L5: 12.18 | M5: 403.06 | N5: 0.35 | O5: 141.07 | P5: Billed | Q5: Paid | R5: 1 | S5: 24 | T5: 46143 | U5: CUST0001|Telco Support | V5: Linked | W5: Billing row links to matching customer/service contract
A6: BILL00005 | B6: CUST0001 | C6: 45778 | D6: Support | E6: Telco Support | F6: CTR-0001-01 | G6: SP001 | H6: Recurring + Usage | I6: 406 | J6: 0 | K6: 17.24 | L6: 12.18 | M6: 411.06 | N6: 0.3 | O6: 123.32 | P6: Billed | Q6: Paid | R6: 1 | S6: 24 | T6: 46143 | U6: CUST0001|Telco Support | V6: Linked | W6: Billing row links to matching customer/service contract
A7: BILL00006 | B7: CUST0001 | C7: 45809 | D7: Support | E7: Telco Support | F7: CTR-0001-01 | G7: SP001 | H7: Recurring + Usage | I7: 406 | J7: 190.57 | K7: 53.35 | L7: 12.18 | M7: 637.74 | N7: 0.24 | O7: 153.06 | P7: Billed | Q7: Pending | R7: 1 | S7: 24 | T7: 46143 | U7: CUST0001|Telco Support | V7: Linked | W7: Billing row links to matching customer/service contract
A8: BILL00007 | B8: CUST0001 | C8: 45839 | D8: Support | E8: Telco Support | F8: CTR-0001-01 | G8: SP001 | H8: Recurring + Usage | I8: 406 | J8: 149.08 | K8: 41.97 | L8: 32.48 | M8: 564.57 | N8: 0.35 | O8: 197.6 | P8: Billed | Q8: Paid | R8: 1 | S8: 24 | T8: 46143 | U8: CUST0001|Telco Support | V8: Linked | W8: Billing row links to matching customer/service contract
A9: BILL00008 | B9: CUST0001 | C9: 45870 | D9: Support | E9: Telco Support | F9: CTR-0001-01 | G9: SP001 | H9: Recurring + Usage | I9: 406 | J9: 0 | K9: 43.42 | L9: 0 | M9: 449.42 | N9: 0.33 | O9: 148.31 | P9: Billed | Q9: Paid | R9: 1 | S9: 24 | T9: 46143 | U9: CUST0001|Telco Support | V9: Linked | W9: Billing row links to matching customer/service contract
A10: BILL00009 | B10: CUST0001 | C10: 45901 | D10: Support | E10: Telco Support | F10: CTR-0001-01 | G10: SP001 | H10: Recurring + Usage | I10: 406 | J10: 0 | K10: 31.63 | L10: 12.18 | M10: 425.45 | N10: 0.31 | O10: 131.89 | P10: Billed | Q10: Pending | R10: 1 | S10: 24 | T10: 46143 | U10: CUST0001|Telco Support | V10: Linked | W10: Billing row links to matching customer/service contract
A11: BILL00010 | B11: CUST0001 | C11: 45931 | D11: Support | E11: Telco Support | F11: CTR-0001-01 | G11: SP001 | H11: Recurring + Usage | I11: 406 | J11: 0 | K11: 46.97 | L11: 0 | M11: 452.97 | N11: 0.26 | O11: 117.77 | P11: Billed | Q11: Paid | R11: 1 | S11: 24 | T11: 46143 | U11: CUST0001|Telco Support | V11: Linked | W11: Billing row links to matching customer/service contract
A12: BILL00011 | B12: CUST0001 | C12: 45962 | D12: Support | E12: Telco Support | F12: CTR-0001-01 | G12: SP001 | H12: Recurring + Usage | I12: 406 | J12: 0 | K12: 40.82 | L12: 0 | M12: 446.82 | N12: 0.29 | O12: 129.58 | P12: Billed | Q12: Paid | R12: 1 | S12: 24 | T12: 46143 | U12: CUST0001|Telco Support | V12: Linked | W12: Billing row links to matching customer/service contract
A13: BILL00012 | B13: CUST0001 | C13: 45992 | D13: Support | E13: Telco Support | F13: CTR-0001-01 | G13: SP001 | H13: Recurring + Usage | I13: 406 | J13: 0 | K13: 53.53 | L13: 20.3 | M13: 439.23 | N13: 0.36 | O13: 158.12 | P13: Billed | Q13: Paid | R13: 1 | S13: 24 | T13: 46143 | U13: CUST0001|Telco Support | V13: Linked | W13: Billing row links to matching customer/service contract
... A2521: BILL02520 | B2521: CUST0100 | C2521: 45992 | D2521: Managed Services | E2521: Cloud IT | F2521: CTR-0100-01 | G2521: SP006 | H2521: Recurring + Usage | I2521: 11307 | J2521: 0 | K2521: 246.83 | L2521: 0 | M2521: 11553.83 | N2521: 0.37 | O2521: 4274.92 | P2521: Billed | Q2521: Paid | R2521: 1 | S2521: 36 | T2521: 46384 | U2521: CUST0100|Cloud IT | V2521: Linked | W2521: Billing row links to matching customer/service contract
A2522: BILL02521 | B2522: CUST0035 | C2522: 45962 | D2522: Managed Services | E2522: Cyber Security | F2522: CTR-0035-01 | G2522: SP008 | H2522: One-Off | I2522: 0 | J2522: 20400 | K2522: 0 | L2522: 0 | M2522: 20400 | N2522: 0.53 | O2522: 10812 | P2522: Billed | Q2522: Pending | R2522: 0 | S2522: 0 | U2522: CUST0035|Cyber Security | V2522: Linked | W2522: Billing row links to matching customer/service contract
A2523: BILL02522 | B2523: CUST0034 | C2523: 45689 | D2523: Managed Services | E2523: Cyber Security | F2523: CTR-0034-01 | G2523: SP006 | H2523: One-Off | I2523: 0 | J2523: 27021 | K2523: 0 | L2523: 0 | M2523: 27021 | N2523: 0.55 | O2523: 14861.55 | P2523: Billed | Q2523: Pending | R2523: 0 | S2523: 0 | U2523: CUST0034|Cyber Security | V2523: Linked | W2523: Billing row links to matching customer/service contract
A2524: BILL02523 | B2524: CUST0035 | C2524: 45689 | D2524: Support | E2524: IT Support | F2524: CTR-0035-01 | G2524: SP008 | H2524: One-Off | I2524: 0 | J2524: 18984 | K2524: 0 | L2524: 0 | M2524: 18984 | N2524: 0.39 | O2524: 7403.76 | P2524: Billed | Q2524: Pending | R2524: 0 | S2524: 0 | U2524: CUST0035|IT Support | V2524: Linked | W2524: Billing row links to matching customer/service contract
A2525: BILL02524 | B2525: CUST0005 | C2525: 45809 | D2525: Support | E2525: IT Support | F2525: CTR-0005-01 | G2525: SP008 | H2525: One-Off | I2525: 0 | J2525: 30958 | K2525: 0 | L2525: 0 | M2525: 30958 | N2525: 0.37 | O2525: 11454.46 | P2525: Billed | Q2525: Paid | R2525: 0 | S2525: 0 | U2525: CUST0005|IT Support | V2525: Linked | W2525: Billing row links to matching customer/service contract
A2526: BILL02525 | B2526: CUST0094 | C2526: 45962 | D2526: Support | E2526: IT Support | F2526: CTR-0094-01 | G2526: SP001 | H2526: One-Off | I2526: 0 | J2526: 11092 | K2526: 0 | L2526: 0 | M2526: 11092 | N2526: 0.37 | O2526: 4104.04 | P2526: Billed | Q2526: Paid | R2526: 0 | S2526: 0 | U2526: CUST0094|IT Support | V2526: Linked | W2526: Billing row links to matching customer/service contract
A2527: BILL02526 | B2527: CUST0094 | C2527: 45717 | D2527: Support | E2527: IT Support | F2527: CTR-0094-01 | G2527: SP001 | H2527: One-Off | I2527: 0 | J2527: 2760 | K2527: 0 | L2527: 0 | M2527: 2760 | N2527: 0.48 | O2527: 1324.8 | P2527: Billed | Q2527: Paid | R2527: 0 | S2527: 0 | U2527: CUST0094|IT Support | V2527: Linked | W2527: Billing row links to matching customer/service contract
A2528: BILL02527 | B2528: CUST0010 | C2528: 45962 | D2528: Managed Services | E2528: Cyber Security | F2528: CTR-0010-01 | G2528: SP008 | H2528: One-Off | I2528: 0 | J2528: 10127 | K2528: 0 | L2528: 0 | M2528: 10127 | N2528: 0.45 | O2528: 4557.15 | P2528: Billed | Q2528: Paid | R2528: 0 | S2528: 0 | U2528: CUST0010|Cyber Security | V2528: Linked | W2528: Billing row links to matching customer/service contract
A2529: BILL02528 | B2529: CUST0021 | C2529: 45901 | D2529: Support | E2529: Telco Support | F2529: CTR-0021-01 | G2529: SP002 | H2529: One-Off | I2529: 0 | J2529: 7312 | K2529: 0 | L2529: 0 | M2529: 7312 | N2529: 0.36 | O2529: 2632.32 | P2529: Billed | Q2529: Paid | R2529: 0 | S2529: 0 | U2529: CUST0021|Telco Support | V2529: Linked | W2529: Billing row links to matching customer/service contract
A2530: BILL02529 | B2530: CUST0067 | C2530: 45839 | D2530: Managed Services | E2530: Cloud IT | F2530: CTR-0067-02 | G2530: SP008 | H2530: One-Off | I2530: 0 | J2530: 20897 | K2530: 0 | L2530: 0 | M2530: 20897 | N2530: 0.36 | O2530: 7522.92 | P2530: Billed | Q2530: Paid | R2530: 0 | S2530: 0 | U2530: CUST0067|Cloud IT | V2530: Linked | W2530: Billing row links to matching customer/service contract
A2531: BILL02530 | B2531: CUST0052 | C2531: 45839 | D2531: Telco | E2531: Hosted Telephony | F2531: CTR-0052-01 | G2531: SP002 | H2531: One-Off | I2531: 0 | J2531: 14343 | K2531: 0 | L2531: 0 | M2531: 14343 | N2531: 0.29 | O2531: 4159.47 | P2531: Billed | Q2531: Paid | R2531: 0 | S2531: 0 | U2531: CUST0052|Hosted Telephony | V2531: Linked | W2531: Billing row links to matching customer/service contract
A2532: BILL02531 | B2532: CUST0036 | C2532: 45689 | D2532: Telco | E2532: Hosted Telephony | F2532: CTR-0036-01 | G2532: SP004 | H2532: One-Off | I2532: 0 | J2532: 20357 | K2532: 0 | L2532: 0 | M2532: 20357 | N2532: 0.41 | O2532: 8346.37 | P2532: Billed | Q2532: Pending | R2532: 0 | S2532: 0 | U2532: CUST0036|Hosted Telephony | V2532: Linked | W2532: Billing row links to matching customer/service contract
A2533: BILL02532 | B2533: CUST0064 | C2533: 45931 | D2533: Support | E2533: Telco Support | F2533: CTR-0064-02 | G2533: SP007 | H2533: One-Off | I2533: 0 | J2533: 27034 | K2533: 0 | L2533: 0 | M2533: 27034 | N2533: 0.35 | O2533: 9461.9 | P2533: Billed | Q2533: Paid | R2533: 0 | S2533: 0 | U2533: CUST0064|Telco Support | V2533: Linked | W2533: Billing row links to matching customer/service contract
... A2601: BILL02600 | B2601: CUST0047 | C2601: 45839 | D2601: Managed Services | E2601: Cyber Security | F2601: CTR-0047-01 | G2601: SP010 | H2601: One-Off | I2601: 0 | J2601: 28926 | K2601: 0 | L2601: 0 | M2601: 28926 | N2601: 0.47 | O2601: 13595.22 | P2601: Billed | Q2601: Paid | R2601: 0 | S2601: 0 | U2601: CUST0047|Cyber Security | V2601: Linked | W2601: Billing row links to matching customer/service contract

Sheet BillingSummaryByService
A1: ServiceCategory | B1: Service | C1: ActiveCustomers | D1: RecurringMRR | E1: AnnualisedRecurringRevenue | F1: OneOffCharges | G1: UsageCharges | H1: Discounts | I1: TotalBilled | J1: GrossProfit | K1: AvgGrossMargin | L1: OverdueBills | M1: CrossSellSignal
A2: Managed Services | B2: Cloud IT | C2: =COUNTA(_xlfn.UNIQUE(_xlfn._xlws.FILTER(ExistingCustomerBilling!$B$2:$B$2601,ExistingCustomerBilling!$E$2:$E$2601=$B2))) | D2: =SUMIFS(ExistingCustomerBilling!$I:$I,ExistingCustomerBilling!$E:$E,$B2,ExistingCustomerBilling!$R:$R,1) | E2: =D2*12 | F2: =SUMIFS(ExistingCustomerBilling!$J:$J,ExistingCustomerBilling!$E:$E,$B2) | G2: =SUMIFS(ExistingCustomerBilling!$K:$K,ExistingCustomerBilling!$E:$E,$B2) | H2: =SUMIFS(ExistingCustomerBilling!$L:$L,ExistingCustomerBilling!$E:$E,$B2) | I2: =SUMIFS(ExistingCustomerBilling!$M:$M,ExistingCustomerBilling!$E:$E,$B2) | J2: =SUMIFS(ExistingCustomerBilling!$O:$O,ExistingCustomerBilling!$E:$E,$B2) | K2: =IFERROR(J2/I2,0) | L2: =COUNTIFS(ExistingCustomerBilling!$E:$E,$B2,ExistingCustomerBilling!$Q:$Q,"Overdue") | M2: =IF(C2<35,"High whitespace / cross-sell potential",IF(K2<0.35,"Margin review","Maintain / expand"))
A3: Managed Services | B3: Modern Workplace | C3: =COUNTA(_xlfn.UNIQUE(_xlfn._xlws.FILTER(ExistingCustomerBilling!$B$2:$B$2601,ExistingCustomerBilling!$E$2:$E$2601=$B3))) | D3: =SUMIFS(ExistingCustomerBilling!$I:$I,ExistingCustomerBilling!$E:$E,$B3,ExistingCustomerBilling!$R:$R,1) | E3: =D3*12 | F3: =SUMIFS(ExistingCustomerBilling!$J:$J,ExistingCustomerBilling!$E:$E,$B3) | G3: =SUMIFS(ExistingCustomerBilling!$K:$K,ExistingCustomerBilling!$E:$E,$B3) | H3: =SUMIFS(ExistingCustomerBilling!$L:$L,ExistingCustomerBilling!$E:$E,$B3) | I3: =SUMIFS(ExistingCustomerBilling!$M:$M,ExistingCustomerBilling!$E:$E,$B3) | J3: =SUMIFS(ExistingCustomerBilling!$O:$O,ExistingCustomerBilling!$E:$E,$B3) | K3: =IFERROR(J3/I3,0) | L3: =COUNTIFS(ExistingCustomerBilling!$E:$E,$B3,ExistingCustomerBilling!$Q:$Q,"Overdue") | M3: =IF(C3<35,"High whitespace / cross-sell potential",IF(K3<0.35,"Margin review","Maintain / expand"))
A4: Managed Services | B4: Cyber Security | C4: =COUNTA(_xlfn.UNIQUE(_xlfn._xlws.FILTER(ExistingCustomerBilling!$B$2:$B$2601,ExistingCustomerBilling!$E$2:$E$2601=$B4))) | D4: =SUMIFS(ExistingCustomerBilling!$I:$I,ExistingCustomerBilling!$E:$E,$B4,ExistingCustomerBilling!$R:$R,1) | E4: =D4*12 | F4: =SUMIFS(ExistingCustomerBilling!$J:$J,ExistingCustomerBilling!$E:$E,$B4) | G4: =SUMIFS(ExistingCustomerBilling!$K:$K,ExistingCustomerBilling!$E:$E,$B4) | H4: =SUMIFS(ExistingCustomerBilling!$L:$L,ExistingCustomerBilling!$E:$E,$B4) | I4: =SUMIFS(ExistingCustomerBilling!$M:$M,ExistingCustomerBilling!$E:$E,$B4) | J4: =SUMIFS(ExistingCustomerBilling!$O:$O,ExistingCustomerBilling!$E:$E,$B4) | K4: =IFERROR(J4/I4,0) | L4: =COUNTIFS(ExistingCustomerBilling!$E:$E,$B4,ExistingCustomerBilling!$Q:$Q,"Overdue") | M4: =IF(C4<35,"High whitespace / cross-sell potential",IF(K4<0.35,"Margin review","Maintain / expand"))
A5: Telco | B5: Connectivity | C5: =COUNTA(_xlfn.UNIQUE(_xlfn._xlws.FILTER(ExistingCustomerBilling!$B$2:$B$2601,ExistingCustomerBilling!$E$2:$E$2601=$B5))) | D5: =SUMIFS(ExistingCustomerBilling!$I:$I,ExistingCustomerBilling!$E:$E,$B5,ExistingCustomerBilling!$R:$R,1) | E5: =D5*12 | F5: =SUMIFS(ExistingCustomerBilling!$J:$J,ExistingCustomerBilling!$E:$E,$B5) | G5: =SUMIFS(ExistingCustomerBilling!$K:$K,ExistingCustomerBilling!$E:$E,$B5) | H5: =SUMIFS(ExistingCustomerBilling!$L:$L,ExistingCustomerBilling!$E:$E,$B5) | I5: =SUMIFS(ExistingCustomerBilling!$M:$M,ExistingCustomerBilling!$E:$E,$B5) | J5: =SUMIFS(ExistingCustomerBilling!$O:$O,ExistingCustomerBilling!$E:$E,$B5) | K5: =IFERROR(J5/I5,0) | L5: =COUNTIFS(ExistingCustomerBilling!$E:$E,$B5,ExistingCustomerBilling!$Q:$Q,"Overdue") | M5: =IF(C5<35,"High whitespace / cross-sell potential",IF(K5<0.35,"Margin review","Maintain / expand"))
A6: Telco | B6: Hosted Telephony | C6: =COUNTA(_xlfn.UNIQUE(_xlfn._xlws.FILTER(ExistingCustomerBilling!$B$2:$B$2601,ExistingCustomerBilling!$E$2:$E$2601=$B6))) | D6: =SUMIFS(ExistingCustomerBilling!$I:$I,ExistingCustomerBilling!$E:$E,$B6,ExistingCustomerBilling!$R:$R,1) | E6: =D6*12 | F6: =SUMIFS(ExistingCustomerBilling!$J:$J,ExistingCustomerBilling!$E:$E,$B6) | G6: =SUMIFS(ExistingCustomerBilling!$K:$K,ExistingCustomerBilling!$E:$E,$B6) | H6: =SUMIFS(ExistingCustomerBilling!$L:$L,ExistingCustomerBilling!$E:$E,$B6) | I6: =SUMIFS(ExistingCustomerBilling!$M:$M,ExistingCustomerBilling!$E:$E,$B6) | J6: =SUMIFS(ExistingCustomerBilling!$O:$O,ExistingCustomerBilling!$E:$E,$B6) | K6: =IFERROR(J6/I6,0) | L6: =COUNTIFS(ExistingCustomerBilling!$E:$E,$B6,ExistingCustomerBilling!$Q:$Q,"Overdue") | M6: =IF(C6<35,"High whitespace / cross-sell potential",IF(K6<0.35,"Margin review","Maintain / expand"))
A7: Support | B7: IT Support | C7: =COUNTA(_xlfn.UNIQUE(_xlfn._xlws.FILTER(ExistingCustomerBilling!$B$2:$B$2601,ExistingCustomerBilling!$E$2:$E$2601=$B7))) | D7: =SUMIFS(ExistingCustomerBilling!$I:$I,ExistingCustomerBilling!$E:$E,$B7,ExistingCustomerBilling!$R:$R,1) | E7: =D7*12 | F7: =SUMIFS(ExistingCustomerBilling!$J:$J,ExistingCustomerBilling!$E:$E,$B7) | G7: =SUMIFS(ExistingCustomerBilling!$K:$K,ExistingCustomerBilling!$E:$E,$B7) | H7: =SUMIFS(ExistingCustomerBilling!$L:$L,ExistingCustomerBilling!$E:$E,$B7) | I7: =SUMIFS(ExistingCustomerBilling!$M:$M,ExistingCustomerBilling!$E:$E,$B7) | J7: =SUMIFS(ExistingCustomerBilling!$O:$O,ExistingCustomerBilling!$E:$E,$B7) | K7: =IFERROR(J7/I7,0) | L7: =COUNTIFS(ExistingCustomerBilling!$E:$E,$B7,ExistingCustomerBilling!$Q:$Q,"Overdue") | M7: =IF(C7<35,"High whitespace / cross-sell potential",IF(K7<0.35,"Margin review","Maintain / expand"))
A8: Support | B8: Telco Support | C8: =COUNTA(_xlfn.UNIQUE(_xlfn._xlws.FILTER(ExistingCustomerBilling!$B$2:$B$2601,ExistingCustomerBilling!$E$2:$E$2601=$B8))) | D8: =SUMIFS(ExistingCustomerBilling!$I:$I,ExistingCustomerBilling!$E:$E,$B8,ExistingCustomerBilling!$R:$R,1) | E8: =D8*12 | F8: =SUMIFS(ExistingCustomerBilling!$J:$J,ExistingCustomerBilling!$E:$E,$B8) | G8: =SUMIFS(ExistingCustomerBilling!$K:$K,ExistingCustomerBilling!$E:$E,$B8) | H8: =SUMIFS(ExistingCustomerBilling!$L:$L,ExistingCustomerBilling!$E:$E,$B8) | I8: =SUMIFS(ExistingCustomerBilling!$M:$M,ExistingCustomerBilling!$E:$E,$B8) | J8: =SUMIFS(ExistingCustomerBilling!$O:$O,ExistingCustomerBilling!$E:$E,$B8) | K8: =IFERROR(J8/I8,0) | L8: =COUNTIFS(ExistingCustomerBilling!$E:$E,$B8,ExistingCustomerBilling!$Q:$Q,"Overdue") | M8: =IF(C8<35,"High whitespace / cross-sell potential",IF(K8<0.35,"Margin review","Maintain / expand"))
A9: TOTAL | B9: All Services | C9: =COUNTA(_xlfn.UNIQUE(ExistingCustomerBilling!$B$2:$B$2601)) | D9: =SUM(D2:D8) | E9: =SUM(E2:E8) | F9: =SUM(F2:F8) | G9: =SUM(G2:G8) | H9: =SUM(H2:H8) | I9: =SUM(I2:I8) | J9: =SUM(J2:J8) | K9: =IFERROR(J9/I9,0) | L9: =SUM(L2:L8) | M9: Portfolio view

Sheet BillingFeatureNotes
A1: Section | B1: Detail
A2: Purpose | B2: This workbook now includes existing customer billing history across Managed Services, Telco and Support services.
A3: Why added | B3: Customer billing data helps the model understand current account value, recurring revenue, gross profit, product penetration, renewal timing and cross-sell whitespace.
A4: Main billing sheet | B4: ExistingCustomerBilling
A5: Summary sheet | B5: BillingSummaryByService
A6: Key model features | B6: MRR, annualised recurring revenue, gross profit, margin, active service count, product penetration, overdue bills, renewal date proximity, usage growth, service mix.
A7: Manager value | B7: Sales managers can identify high-value customers, underpenetrated accounts, cross-sell opportunities, service gaps and renewal risk.
A8: Data scientist value | B8: The model can test whether billing patterns improve prediction accuracy and whether product/service mix changes salesperson performance predictions.
A9: Future extension | B9: When call transcripts or salesperson notes are added, model behaviour can be compared before and after the new features are introduced.
A10: Important caveat | B10: The billing data is simulated for demo purposes and should be replaced with approved real billing data before production use.

Sheet Contracts
A1: ContractID | B1: CustomerID | C1: AccountOwnerID | D1: ContractName | E1: ContractType | F1: ContractStatus | G1: OriginalStartDate | H1: CurrentStartDate | I1: OriginalEndDate | J1: CurrentEndDate | K1: ContractTermMonths | L1: RenewalWindowDays | M1: DaysToRenewal | N1: AutoRenewal | O1: EndDateChangeCount | P1: RollbackCount | Q1: RollbackAllowed | R1: HealthCheckRequired | S1: HealthCheckReason | T1: SuggestedAction | U1: ContractMRR | V1: ContractARR | W1: EstimatedAnnualGrossProfit | X1: RenewalRisk | Y1: SnapshotDate
A2: CTR-0001-01 | B2: CUST0001 | C2: SP001 | D2: CUST0001 Support Agreement 1 | E2: Support Agreement | F2: Expired - Rolling | G2: 45962 | H2: 45962 | I2: 46682 | J2: 46112 | K2: 24 | L2: 120 | M2: -137 | N2: 1 | O2: 0 | P2: 0 | Q2: 1 | R2: 1 | S2: Contract has passed end date and appears to be rolling or needs review | T2: Immediate contract health check and renewal confirmation | U2: 374.77 | V2: 4497.24 | W2: 1394.16 | X2: Medium | Y2: 46249
A3: CTR-0002-01 | B3: CUST0002 | C3: SP004 | D3: CUST0002 Multi-Service Agreement 1 | E3: Multi-Service Agreement | F3: Upcoming Renewal | G3: 45597 | H3: 45597 | I3: 46317 | J3: 46282 | K3: 24 | L3: 120 | M3: 33 | N3: 0 | O3: 1 | P3: 1 | Q3: 1 | R3: 1 | S3: Renewal due within 60 days | T3: Schedule renewal and service-value review | U3: 7001 | V3: 84012 | W3: 29133.12 | X3: Medium | Y3: 46249
A4: CTR-0003-01 | B4: CUST0003 | C4: SP006 | D4: CUST0003 Telco Agreement 1 | E4: Telco Agreement | F4: Upcoming Renewal | G4: 45017 | H4: 45017 | I4: 45377 | J4: 46331 | K4: 12 | L4: 120 | M4: 82 | N4: 1 | O4: 0 | P4: 0 | Q4: 0 | R4: 1 | S4: Renewal due within 120 days | T4: Plan proactive health check and whitespace review | U4: 2790 | V4: 33480 | W4: 10044 | X4: High | Y4: 46249
A5: CTR-0004-01 | B5: CUST0004 | C5: SP007 | D5: CUST0004 Multi-Service Agreement 1 | E5: Multi-Service Agreement | F5: Active | G5: 45337 | H5: 45337 | I5: 45697 | J5: 46934 | K5: 12 | L5: 120 | M5: 685 | N5: 1 | O5: 3 | P5: 1 | Q5: 1 | R5: 0 | T5: Monitor | U5: 617 | V5: 7404 | W5: 2369.28 | X5: Low | Y5: 46249
A6: CTR-0004-02 | B6: CUST0004 | C6: SP007 | D6: CUST0004 Multi-Service Agreement 2 | E6: Multi-Service Agreement | F6: Upcoming Renewal | G6: 45337 | H6: 45337 | I6: 46417 | J6: 46259 | K6: 36 | L6: 120 | M6: 10 | N6: 1 | O6: 2 | P6: 0 | Q6: 1 | R6: 1 | S6: Renewal due within 30 days | T6: Urgent customer renewal health check | U6: 8767 | V6: 105204 | W6: 49559.04 | X6: Low | Y6: 46249
A7: CTR-0004-03 | B7: CUST0004 | C7: SP007 | D7: CUST0004 Managed Service Agreement 3 | E7: Managed Service Agreement | F7: Active | G7: 45792 | H7: 45792 | I7: 46512 | J7: 46736 | K7: 24 | L7: 120 | M7: 487 | N7: 0 | O7: 0 | P7: 0 | Q7: 1 | R7: 0 | T7: Monitor | U7: 8937 | V7: 107244 | W7: 45042.48 | X7: Low | Y7: 46249
A8: CTR-0005-01 | B8: CUST0005 | C8: SP008 | D8: CUST0005 Multi-Service Agreement 1 | E8: Multi-Service Agreement | F8: Upcoming Renewal | G8: 45689 | H8: 45689 | I8: 46409 | J8: 46355 | K8: 24 | L8: 120 | M8: 106 | N8: 0 | O8: 0 | P8: 0 | Q8: 0 | R8: 1 | S8: Renewal due within 120 days | T8: Plan proactive health check and whitespace review | U8: 5814 | V8: 69768 | W8: 27209.52 | X8: Low | Y8: 46249
A9: CTR-0005-02 | B9: CUST0005 | C9: SP008 | D9: CUST0005 Multi-Service Agreement 2 | E9: Multi-Service Agreement | F9: Upcoming Renewal | G9: 45703 | H9: 45703 | I9: 46063 | J9: 46259 | K9: 12 | L9: 120 | M9: 10 | N9: 1 | O9: 2 | P9: 0 | Q9: 1 | R9: 1 | S9: Renewal due within 30 days | T9: Urgent customer renewal health check | U9: 1295 | V9: 15540 | W9: 5088.48 | X9: Medium | Y9: 46249
A10: CTR-0005-03 | B10: CUST0005 | C10: SP008 | D10: CUST0005 Support Agreement 3 | E10: Support Agreement | F10: Upcoming Renewal | G10: 45519 | H10: 45519 | I10: 46239 | J10: 46272 | K10: 24 | L10: 120 | M10: 23 | N10: 1 | O10: 3 | P10: 0 | Q10: 1 | R10: 1 | S10: Renewal due within 30 days | T10: Urgent customer renewal health check | U10: 1954 | V10: 23448 | W10: 7034.4 | X10: Medium | Y10: 46249
A11: CTR-0006-01 | B11: CUST0006 | C11: SP006 | D11: CUST0006 Multi-Service Agreement 1 | E11: Multi-Service Agreement | F11: Expired - Rolling | G11: 45184 | H11: 45184 | I11: 45544 | J11: 46222 | K11: 12 | L11: 120 | M11: -27 | N11: 1 | O11: 3 | P11: 0 | Q11: 1 | R11: 1 | S11: Contract has passed end date and appears to be rolling or needs review | T11: Immediate contract health check and renewal confirmation | U11: 3213 | V11: 38556 | W11: 11525.4 | X11: Medium | Y11: 46249
A12: CTR-0007-01 | B12: CUST0007 | C12: SP006 | D12: CUST0007 Multi-Service Agreement 1 | E12: Multi-Service Agreement | F12: Expired - Rolling | G12: 45383 | H12: 45383 | I12: 45743 | J12: 46160 | K12: 12 | L12: 120 | M12: -89 | N12: 1 | O12: 1 | P12: 1 | Q12: 1 | R12: 1 | S12: Contract has passed end date and appears to be rolling or needs review | T12: Immediate contract health check and renewal confirmation | U12: 1830.46 | V12: 21965.52 | W12: 8868.48 | X12: Low | Y12: 46249
A13: CTR-0008-01 | B13: CUST0008 | C13: SP003 | D13: CUST0008 Support Agreement 1 | E13: Support Agreement | F13: Active | G13: 45184 | H13: 45184 | I13: 45544 | J13: 46449 | K13: 12 | L13: 120 | M13: 200 | N13: 0 | O13: 0 | P13: 0 | Q13: 1 | R13: 0 | T13: Monitor | U13: 2313 | V13: 27756 | W13: 8049.24 | X13: Low | Y13: 46249
A14: CTR-0008-02 | B14: CUST0008 | C14: SP003 | D14: CUST0008 Telco Agreement 2 | E14: Telco Agreement | F14: Active | G14: 45519 | H14: 45519 | I14: 45879 | J14: 46595 | K14: 12 | L14: 120 | M14: 346 | N14: 0 | O14: 1 | P14: 1 | Q14: 1 | R14: 0 | T14: Monitor | U14: 2649 | V14: 31788 | W14: 10807.92 | X14: Low | Y14: 46249
A15: CTR-0008-03 | B15: CUST0008 | C15: SP003 | D15: CUST0008 Multi-Service Agreement 3 | E15: Multi-Service Agreement | F15: Active | G15: 45000 | H15: 45000 | I15: 45720 | J15: 46825 | K15: 24 | L15: 120 | M15: 576 | N15: 0 | O15: 1 | P15: 0 | Q15: 0 | R15: 0 | T15: Monitor | U15: 2476 | V15: 29712 | W15: 12776.16 | X15: Low | Y15: 46249
A16: CTR-0009-01 | B16: CUST0009 | C16: SP009 | D16: CUST0009 Support Agreement 1 | E16: Support Agreement | F16: Upcoming Renewal | G16: 45566 | H16: 45566 | I16: 46286 | J16: 46315 | K16: 24 | L16: 120 | M16: 66 | N16: 0 | O16: 0 | P16: 0 | Q16: 1 | R16: 1 | S16: Renewal due within 120 days | T16: Plan proactive health check and whitespace review | U16: 4829.54 | V16: 57954.48 | W16: 25500 | X16: Low | Y16: 46249
A17: CTR-0010-01 | B17: CUST0010 | C17: SP008 | D17: CUST0010 Multi-Service Agreement 1 | E17: Multi-Service Agreement | F17: Upcoming Renewal | G17: 45505 | H17: 45505 | I17: 46585 | J17: 46317 | K17: 36 | L17: 120 | M17: 68 | N17: 0 | O17: 0 | P17: 0 | Q17: 1 | R17: 1 | S17: Renewal due within 120 days | T17: Plan proactive health check and whitespace review | U17: 5966 | V17: 71592 | W17: 31500.48 | X17: Medium | Y17: 46249
A18: CTR-0010-02 | B18: CUST0010 | C18: SP008 | D18: CUST0010 Multi-Service Agreement 2 | E18: Multi-Service Agreement | F18: Active | G18: 45200 | H18: 45200 | I18: 46280 | J18: 46681 | K18: 36 | L18: 120 | M18: 432 | N18: 1 | O18: 0 | P18: 0 | Q18: 0 | R18: 0 | T18: Monitor | U18: 1080 | V18: 12960 | W18: 4017.6 | X18: Low | Y18: 46249
A19: CTR-0010-03 | B19: CUST0010 | C19: SP008 | D19: CUST0010 Managed Service Agreement 3 | E19: Managed Service Agreement | F19: Active | G19: 45200 | H19: 45200 | I19: 46280 | J19: 46464 | K19: 36 | L19: 120 | M19: 215 | N19: 0 | O19: 0 | P19: 0 | Q19: 0 | R19: 0 | T19: Monitor | U19: 0 | V19: 0 | W19: 0 | X19: Low | Y19: 46249
A20: CTR-0011-01 | B20: CUST0011 | C20: SP005 | D20: CUST0011 Support Agreement 1 | E20: Support Agreement | F20: Active | G20: 45976 | H20: 45976 | I20: 46696 | J20: 46828 | K20: 24 | L20: 120 | M20: 579 | N20: 1 | O20: 3 | P20: 2 | Q20: 1 | R20: 0 | T20: Monitor | U20: 449 | V20: 5388 | W20: 1616.4 | X20: Low | Y20: 46249
A21: CTR-0012-01 | B21: CUST0012 | C21: SP010 | D21: CUST0012 Managed Service Agreement 1 | E21: Managed Service Agreement | F21: Upcoming Renewal | G21: 45170 | H21: 45170 | I21: 46250 | J21: 46353 | K21: 36 | L21: 120 | M21: 104 | N21: 1 | O21: 0 | P21: 0 | Q21: 0 | R21: 1 | S21: Renewal due within 120 days | T21: Plan proactive health check and whitespace review | U21: 1291.71 | V21: 15500.52 | W21: 5890.2 | X21: Medium | Y21: 46249
A22: CTR-0013-01 | B22: CUST0013 | C22: SP005 | D22: CUST0013 Multi-Service Agreement 1 | E22: Multi-Service Agreement | F22: Active | G22: 45778 | H22: 45778 | I22: 46858 | J22: 46880 | K22: 36 | L22: 120 | M22: 631 | N22: 0 | O22: 0 | P22: 0 | Q22: 1 | R22: 0 | T22: Monitor | U22: 4144 | V22: 49728 | W22: 19104.48 | X22: Low | Y22: 46249
A23: CTR-0014-01 | B23: CUST0014 | C23: SP003 | D23: CUST0014 Multi-Service Agreement 1 | E23: Multi-Service Agreement | F23: Expired - Needs Review | G23: 45306 | H23: 45306 | I23: 46026 | J23: 46190 | K23: 24 | L23: 120 | M23: -59 | N23: 0 | O23: 0 | P23: 0 | Q23: 0 | R23: 1 | S23: Contract has passed end date and appears to be rolling or needs review | T23: Immediate contract health check and renewal confirmation | U23: 5978 | V23: 71736 | W23: 29558.28 | X23: High | Y23: 46249
A24: CTR-0015-01 | B24: CUST0015 | C24: SP009 | D24: CUST0015 Multi-Service Agreement 1 | E24: Multi-Service Agreement | F24: Upcoming Renewal | G24: 45519 | H24: 45519 | I24: 46239 | J24: 46290 | K24: 24 | L24: 120 | M24: 41 | N24: 1 | O24: 0 | P24: 0 | Q24: 1 | R24: 1 | S24: Renewal due within 60 days | T24: Schedule renewal and service-value review | U24: 6220 | V24: 74640 | W24: 30361.44 | X24: Low | Y24: 46249
A25: CTR-0015-02 | B25: CUST0015 | C25: SP009 | D25: CUST0015 Multi-Service Agreement 2 | E25: Multi-Service Agreement | F25: Expired - Needs Review | G25: 45413 | H25: 45413 | I25: 46493 | J25: 46182 | K25: 36 | L25: 120 | M25: -67 | N25: 1 | O25: 0 | P25: 0 | Q25: 0 | R25: 1 | S25: Contract has passed end date and appears to be rolling or needs review | T25: Immediate contract health check and renewal confirmation | U25: 8832 | V25: 105984 | W25: 44513.28 | X25: Low | Y25: 46249
A26: CTR-0016-01 | B26: CUST0016 | C26: SP007 | D26: CUST0016 Managed Service Agreement 1 | E26: Managed Service Agreement | F26: Active | G26: 45884 | H26: 45884 | I26: 46244 | J26: 46850 | K26: 12 | L26: 120 | M26: 601 | N26: 1 | O26: 1 | P26: 0 | Q26: 1 | R26: 0 | T26: Monitor | U26: 8414 | V26: 100968 | W26: 42406.56 | X26: Low | Y26: 46249
A27: CTR-0017-01 | B27: CUST0017 | C27: SP005 | D27: CUST0017 Managed Service Agreement 1 | E27: Managed Service Agreement | F27: Active | G27: 45275 | H27: 45275 | I27: 45635 | J27: 46388 | K27: 12 | L27: 120 | M27: 139 | N27: 1 | O27: 1 | P27: 0 | Q27: 1 | R27: 0 | T27: Monitor | U27: 11431 | V27: 137172 | W27: 56240.52 | X27: Low | Y27: 46249
A28: CTR-0017-02 | B28: CUST0017 | C28: SP005 | D28: CUST0017 Managed Service Agreement 2 | E28: Managed Service Agreement | F28: Active | G28: 45931 | H28: 45931 | I28: 46291 | J28: 46715 | K28: 12 | L28: 120 | M28: 466 | N28: 0 | O28: 2 | P28: 1 | Q28: 1 | R28: 0 | T28: Monitor | U28: 1624 | V28: 19488 | W28: 9549.12 | X28: Low | Y28: 46249
A29: CTR-0018-01 | B29: CUST0018 | C29: SP004 | D29: CUST0018 Support Agreement 1 | E29: Support Agreement | F29: Upcoming Renewal | G29: 44972 | H29: 44972 | I29: 46052 | J29: 46279 | K29: 36 | L29: 120 | M29: 30 | N29: 0 | O29: 0 | P29: 0 | Q29: 0 | R29: 1 | S29: Renewal due within 30 days | T29: Urgent customer renewal health check | U29: 2240 | V29: 26880 | W29: 8064 | X29: Low | Y29: 46249
A30: CTR-0018-02 | B30: CUST0018 | C30: SP004 | D30: CUST0018 Managed Service Agreement 2 | E30: Managed Service Agreement | F30: Upcoming Renewal | G30: 45823 | H30: 45823 | I30: 46903 | J30: 46289 | K30: 36 | L30: 120 | M30: 40 | N30: 1 | O30: 4 | P30: 0 | Q30: 1 | R30: 1 | S30: Renewal due within 60 days | T30: Schedule renewal and service-value review | U30: 7694 | V30: 92328 | W30: 44317.44 | X30: Medium | Y30: 46249
A31: CTR-0019-01 | B31: CUST0019 | C31: SP002 | D31: CUST0019 Support Agreement 1 | E31: Support Agreement | F31: Upcoming Renewal | G31: 45611 | H31: 45611 | I31: 46331 | J31: 46254 | K31: 24 | L31: 120 | M31: 5 | N31: 0 | O31: 1 | P31: 1 | Q31: 1 | R31: 1 | S31: Renewal due within 30 days | T31: Urgent customer renewal health check | U31: 1020.92 | V31: 12251.04 | W31: 3675.36 | X31: High | Y31: 46249
A32: CTR-0020-01 | B32: CUST0020 | C32: SP006 | D32: CUST0020 Multi-Service Agreement 1 | E32: Multi-Service Agreement | F32: Expired - Rolling | G32: 45031 | H32: 45031 | I32: 45391 | J32: 46128 | K32: 12 | L32: 120 | M32: -121 | N32: 1 | O32: 1 | P32: 0 | Q32: 0 | R32: 1 | S32: Contract has passed end date and appears to be rolling or needs review | T32: Immediate contract health check and renewal confirmation | U32: 12266 | V32: 147192 | W32: 60666.48 | X32: Medium | Y32: 46249
A33: CTR-0020-02 | B33: CUST0020 | C33: SP006 | D33: CUST0020 Support Agreement 2 | E33: Support Agreement | F33: Expired - Rolling | G33: 45108 | H33: 45108 | I33: 45468 | J33: 46107 | K33: 12 | L33: 120 | M33: -142 | N33: 0 | O33: 0 | P33: 0 | Q33: 1 | R33: 1 | S33: Contract has passed end date and appears to be rolling or needs review | T33: Immediate contract health check and renewal confirmation | U33: 3604 | V33: 43248 | W33: 18596.64 | X33: Medium | Y33: 46249
A34: CTR-0021-01 | B34: CUST0021 | C34: SP002 | D34: CUST0021 Multi-Service Agreement 1 | E34: Multi-Service Agreement | F34: Upcoming Renewal | G34: 45566 | H34: 45566 | I34: 46286 | J34: 46363 | K34: 24 | L34: 120 | M34: 114 | N34: 1 | O34: 0 | P34: 0 | Q34: 1 | R34: 1 | S34: Renewal due within 120 days | T34: Plan proactive health check and whitespace review | U34: 2845 | V34: 34140 | W34: 11949 | X34: Medium | Y34: 46249
A35: CTR-0021-02 | B35: CUST0021 | C35: SP002 | D35: CUST0021 Managed Service Agreement 2 | E35: Managed Service Agreement | F35: Upcoming Renewal | G35: 45778 | H35: 45778 | I35: 46858 | J35: 46354 | K35: 36 | L35: 120 | M35: 105 | N35: 0 | O35: 3 | P35: 0 | Q35: 1 | R35: 1 | S35: Renewal due within 120 days | T35: Plan proactive health check and whitespace review | U35: 7961 | V35: 95532 | W35: 45855.36 | X35: Low | Y35: 46249
A36: CTR-0022-01 | B36: CUST0022 | C36: SP009 | D36: CUST0022 Multi-Service Agreement 1 | E36: Multi-Service Agreement | F36: Upcoming Renewal | G36: 45792 | H36: 45792 | I36: 46512 | J36: 46346 | K36: 24 | L36: 120 | M36: 97 | N36: 1 | O36: 1 | P36: 1 | Q36: 1 | R36: 1 | S36: Renewal due within 120 days | T36: Plan proactive health check and whitespace review | U36: 6153 | V36: 73836 | W36: 27032.04 | X36: High | Y36: 46249
A37: CTR-0023-01 | B37: CUST0023 | C37: SP006 | D37: CUST0023 Multi-Service Agreement 1 | E37: Multi-Service Agreement | F37: Active | G37: 45366 | H37: 45366 | I37: 46086 | J37: 46407 | K37: 24 | L37: 120 | M37: 158 | N37: 1 | O37: 1 | P37: 0 | Q37: 0 | R37: 0 | T37: Monitor | U37: 5818 | V37: 69816 | W37: 28841.4 | X37: Low | Y37: 46249
A38: CTR-0023-02 | B38: CUST0023 | C38: SP006 | D38: CUST0023 Telco Agreement 2 | E38: Telco Agreement | F38: Expired - Needs Review | G38: 45292 | H38: 45292 | I38: 45652 | J38: 46205 | K38: 12 | L38: 120 | M38: -44 | N38: 0 | O38: 0 | P38: 0 | Q38: 1 | R38: 1 | S38: Contract has passed end date and appears to be rolling or needs review | T38: Immediate contract health check and renewal confirmation | U38: 1871 | V38: 22452 | W38: 7184.64 | X38: Low | Y38: 46249
A39: CTR-0024-01 | B39: CUST0024 | C39: SP001 | D39: CUST0024 Multi-Service Agreement 1 | E39: Multi-Service Agreement | F39: Upcoming Renewal | G39: 44958 | H39: 44958 | I39: 46038 | J39: 46293 | K39: 36 | L39: 120 | M39: 44 | N39: 1 | O39: 3 | P39: 0 | Q39: 1 | R39: 1 | S39: Renewal due within 60 days | T39: Schedule renewal and service-value review | U39: 8558 | V39: 102696 | W39: 41794.2 | X39: Low | Y39: 46249
